Workbook

Sheet Dashboard
B1: Data Center Cooling Water Management — M&E Dashboard
B2: 50 MW IT design case · US customary units · yellow = input, green = live formula
B5: Scenario & source controls
B6: Water source | C6: Municipal Potable | E6: Dropdown — pulls Source Library column
B7: Active scenario (Mass Balance view) | C7: Corrugated Fill + High CoC | E7: Dropdown — drives the Process Flow Mass Balance sheet
B8: IT load | C8: 50 | D8: MW
B9: Design wet-bulb temperature | C9: 76 | D9: °F
B10: Average IT utilization | C10: 0.8 | D10: -
B11: RO / IX demineralization on (1/0) | C11: 0 | D11: - | E11: Skippable demineralization step
B13: Scenario levers
B14: Lever | C14: Current Baseline | D14: Corrugated Fill + High CoC | E14: Unit
B15: Target cycles of concentration (2–10) | C15: 4 | D15: 10 | E15: cycles | F15: Clipped by LEED/LSI/drift limits
B16: Blowdown recovery RO on (1/0) | C16: 0 | D16: 1 | E16: -
B18: Key performance indicators
B19: KPI | C19: Current Baseline | D19: Optimized | E19: Δ (Opt − Base) | F19: Unit
B20: Cooling load | C20: ='Cooling Tower & Corrugated Fill'!$C$46 | D20: ='Cooling Tower & Corrugated Fill'!$D$46 | E20: =D20-C20 | F20: MW
B21: Cooling load | C21: ='Cooling Tower & Corrugated Fill'!$C$47 | D21: ='Cooling Tower & Corrugated Fill'!$D$47 | E21: =D21-C21 | F21: tons
B22: Tower heat-rejection load | C22: ='Cooling Tower & Corrugated Fill'!$C$57 | D22: ='Cooling Tower & Corrugated Fill'!$D$57 | E22: =D22-C22 | F22: tons
B23: Chiller COP | C23: ='Cooling Tower & Corrugated Fill'!$C$54 | D23: ='Cooling Tower & Corrugated Fill'!$D$54 | E23: =D23-C23 | F23: -
B24: Tower approach | C24: ='Cooling Tower & Corrugated Fill'!$C$50 | D24: ='Cooling Tower & Corrugated Fill'!$D$50 | E24: =D24-C24 | F24: °F
B25: Cycles of concentration (operating) | C25: ='Cooling Tower & Corrugated Fill'!$C$75 | D25: ='Cooling Tower & Corrugated Fill'!$D$75 | E25: =D25-C25 | F25: cycles
B26: Raw water intake | C26: ='Cooling Tower & Corrugated Fill'!$C$86 | D26: ='Cooling Tower & Corrugated Fill'!$D$86 | E26: =D26-C26 | F26: gpd
B27: Raw water intake | C27: ='Cooling Tower & Corrugated Fill'!$C$87 | D27: ='Cooling Tower & Corrugated Fill'!$D$87 | E27: =D27-C27 | F27: m³/d
B28: Evaporation loss | C28: ='Cooling Tower & Corrugated Fill'!$C$60 | D28: ='Cooling Tower & Corrugated Fill'!$D$60 | E28: =D28-C28 | F28: gpd
B29: Drift loss | C29: ='Cooling Tower & Corrugated Fill'!$C$61 | D29: ='Cooling Tower & Corrugated Fill'!$D$61 | E29: =D29-C29 | F29: gpd
B30: Blowdown (bleed-off) | C30: ='Cooling Tower & Corrugated Fill'!$C$80 | D30: ='Cooling Tower & Corrugated Fill'!$D$80 | E30: =D30-C30 | F30: gpd
B31: Total discharge to sewer | C31: ='Cooling Tower & Corrugated Fill'!$C$89 | D31: ='Cooling Tower & Corrugated Fill'!$D$89 | E31: =D31-C31 | F31: gpd
B32: WUE (water usage effectiveness) | C32: ='Cooling Tower & Corrugated Fill'!$C$90 | D32: ='Cooling Tower & Corrugated Fill'!$D$90 | E32: =D32-C32 | F32: L/kWh IT
B33: Cooling + water plant power | C33: ='Pumping & Fan Hydraulics'!$C$47 | D33: ='Pumping & Fan Hydraulics'!$D$47 | E33: =D33-C33 | F33: kW
B34: Cooling share of PUE | C34: ='Pumping & Fan Hydraulics'!$C$48 | D34: ='Pumping & Fan Hydraulics'!$D$48 | E34: =D34-C34 | F34: -
B35: PUE (incl. other overhead) | C35: ='Pumping & Fan Hydraulics'!$C$49 | D35: ='Pumping & Fan Hydraulics'!$D$49 | E35: =D35-C35 | F35: -
B36: Water-system energy intensity | C36: ='Pumping & Fan Hydraulics'!$C$50 | D36: ='Pumping & Fan Hydraulics'!$D$50 | E36: =D36-C36 | F36: kWh/m³
B37: Annual operating cost (incl. carbon) | C37: ='Financial & LCC Analysis'!$C$51 | D37: ='Financial & LCC Analysis'!$D$51 | E37: =D37-C37 | F37: $/yr
B38: CO₂e emissions | C38: ='Financial & LCC Analysis'!$C$41 | D38: ='Financial & LCC Analysis'!$D$41 | E38: =D38-C38 | F38: t/yr
B39: LEED v4 WE cooling-tower points | C39: ='Cooling Tower & Corrugated Fill'!$C$125 | D39: ='Cooling Tower & Corrugated Fill'!$D$125 | E39: =D39-C39 | F39: pts
B40: Legionella annual inhalation risk | C40: ='Disinfection & Microbial Risk'!$C$68 | D40: ='Disinfection & Microbial Risk'!$D$68 | E40: =D40-C40 | F40: per yr
B42: Compliance & engineering checks
B43: Check | C43: Current Baseline | D43: Optimized | F43: Basis
B44: CoC limiting constraint | C44: ="Limited by "&'Cooling Tower & Corrugated Fill'!$C$74 | D44: ="Limited by "&'Cooling Tower & Corrugated Fill'!$D$74 | F44: LEED / LSI / drift / target
B45: CoC feasible with this source | C45: =IF('Cooling Tower & Corrugated Fill'!$C$73>='Cooling Tower & Corrugated Fill'!$C$15,"✅ Feasible","❌ Enable RO/IX") | D45: =IF('Cooling Tower & Corrugated Fill'!$D$73>='Cooling Tower & Corrugated Fill'!$C$15,"✅ Feasible","❌ Enable RO/IX") | F45: ≥ min CoC
...

Sheet Process Flow Mass Balance
B1: Process Flow Mass Balance — node by node
B2: Q_out = Q_in − Q_reject − Q_evap ; C_out,j = [Q_in·C_in,j·(1 − R_j) + Dosing_j] / Q_out | D2: ="Active scenario: "&'Dashboard'!$C$7
B5: 1. Node configuration (toggle steps on/off)
B6: Process step | C6: On (1/0) | D6: Recovery Q_out/Q_in | E6: Energy kWh/kgal | F6: LRV virus | G6: LRV protozoa | H6: LRV bacteria | I6: pH out (blank = pass) | J6: Effective recovery | K6: Relative inflow Q_in/Q_intake | L6: Energy used kWh/kgal
B7: Raw Water Intake | C7: 1 | D7: 1 | E7: 1.5 | F7: 0 | G7: 0 | H7: 0 | J7: =IF(C7=1,D7,1) | K7: 1 | L7: =IF(C7=1,E7,0)
B8: Coagulation / Flocculation / Sedimentation | C8: 1 | D8: 0.98 | E8: 0.1 | F8: 1 | G8: 0.5 | H8: 1 | J8: =IF(C8=1,D8,1) | K8: =K7*J7 | L8: =IF(C8=1,E8,0)
B9: Multi-Media Filtration | C9: 1 | D9: 0.97 | E9: 0.1 | F9: 1 | G9: 2 | H9: 1 | J9: =IF(C9=1,D9,1) | K9: =K8*J8 | L9: =IF(C9=1,E9,0)
B10: Ultrafiltration | C10: 1 | D10: 0.95 | E10: 0.4 | F10: 4 | G10: 4 | H10: 4 | J10: =IF(C10=1,D10,1) | K10: =K9*J9 | L10: =IF(C10=1,E10,0)
B11: RO / IX Demineralization | C11: ='Dashboard'!$C$11 | D11: 0.8 | F11: 1.5 | G11: 1.5 | H11: 1.5 | I11: 6.5 | J11: =IF(C11=1,D11,1) | K11: =K10*J10 | L11: =IF(C11=1,IF(ISNUMBER(E11),E11,(0.3+0.1*'Process Flow Mass Balance'!$G$54/1000)*1000*0.00378541),0)
B12: Chlorine Contact (CT) | C12: 1 | D12: 1 | E12: 0.05 | F12: 0 | G12: 0 | H12: 0 | J12: =IF(C12=1,D12,1) | K12: =K11*J11 | L12: =IF(C12=1,E12,0)
B14: Overall train recovery Π(effective recovery) | C14: =PRODUCT(J7:J12) | D14: -
B15: Treatment energy per gallon of intake | C15: =SUMPRODUCT('Process Flow Mass Balance'!$L$7:$L$12,'Process Flow Mass Balance'!$K$7:$K$12)/1000 | D15: kWh/gal | E15: RO blank energy → 0.3 + 0.1·TDS(g/L) kWh/m³ (screening)
B17: 2. Coagulation / sedimentation — Stokes' law settling
B18: Floc particle diameter | C18: 150 | D18: µm
B19: Particle density ρp | C19: 1065 | D19: kg/m³
B20: Water density ρw | C20: 1000 | D20: kg/m³
B21: Dynamic viscosity μ (15 °C) | C21: 0.00113 | D21: Pa·s
B22: Clarifier overflow rate | C22: 1.5 | D22: m/h
B23: Design TSS removal | C23: 0.9 | D23: -
B24: Settling velocity v_s = g(ρp − ρw)d²/(18μ) | C24: =9.81*('Process Flow Mass Balance'!$C$19-'Process Flow Mass Balance'!$C$20)*('Process Flow Mass Balance'!$C$18*0.000001)^2/(18*'Process Flow Mass Balance'!$C$21) | D24: m/s
B25: Settling velocity | C25: ='Process Flow Mass Balance'!$C$24*3600 | D25: m/h
B26: Achieved TSS removal = R_design × MIN(1, v_s/SOR) | C26: ='Process Flow Mass Balance'!$C$23*MIN(1,'Process Flow Mass Balance'!$C$25/'Process Flow Mass Balance'!$C$22) | D26: -
B27: Alum dose | C27: 10 | D27: mg/L
B29: 3. Removal fraction R_j (mass to waste) — RO row = 1 − Y·(1 − rejection)
B30: Process step | C30: EC | D30: TDS | E30: SiO₂ | F30: Na⁺ | G30: Ca²⁺ | H30: Mg²⁺ | I30: Cl⁻ | J30: PO₄³⁻ | K30: SO₄²⁻ | L30: Alk (CaCO₃) | M30: Free Cl₂ | N30: TSS | O30: BOD₅ | P30: COD
B31: RO membrane rejection (input) | C31: 0.99 | D31: 0.99 | E31: 0.98 | F31: 0.985 | G31: 0.995 | H31: 0.995 | I31: 0.985 | J31: 0.995 | K31: 0.995 | L31: 0.97 | M31: 1 | N31: 1 | O31: 0.9 | P31: 0.9
B32: Raw Water Intake | C32: 0 | D32: 0 | E32: 0 | F32: 0 | G32: 0 | H32: 0 | I32: 0 | J32: 0 | K32: 0 | L32: 0 | M32: 0 | N32: 0 | O32: 0 | P32: 0
B33: Coagulation / Flocculation / Sedimentation | C33: 0 | D33: 0 | E33: 0 | F33: 0 | G33: 0 | H33: 0 | I33: 0 | J33: 0.8 | K33: 0 | L33: 0 | M33: 0 | N33: ='Process Flow Mass Balance'!$C$26 | O33: 0.3 | P33: 0.3
B34: Multi-Media Filtration | C34: 0 | D34: 0 | E34: 0 | F34: 0 | G34: 0 | H34: 0 | I34: 0 | J34: 0 | K34: 0 | L34: 0 | M34: 0 | N34: 0.8 | O34: 0.1 | P34: 0.1
B35: Ultrafiltration | C35: 0 | D35: 0 | E35: 0 | F35: 0 | G35: 0 | H35: 0 | I35: 0 | J35: 0 | K35: 0 | L35: 0 | M35: 0 | N35: 0.999 | O35: 0.2 | P35: 0.15
B36: RO / IX Demineralization | C36: =1-'Process Flow Mass Balance'!$D$11*(1-'Process Flow Mass Balance'!$C$31) | D36: =1-'Process Flow Mass Balance'!$D$11*(1-'Process Flow Mass Balance'!$D$31) | E36: =1-'Process Flow Mass Balance'!$D$11*(1-'Process Flow Mass Balance'!$E$31) | F36: =1-'Process Flow Mass Balance'!$D$11*(1-'Process Flow Mass Balance'!$F$31) | G36: =1-'Process Flow Mass Balance'!$D$11*(1-'Process Flow Mass Balance'!$G$31) | H36: =1-'Process Flow Mass Balance'!$D$11*(1-'Process Flow Mass Balance'!$H$31) | I36: =1-'Process Flow Mass Balance'!$D$11*(1-'Process Flow Mass Balance'!$I$31) | J36: =1-'Process Flow Mass Balance'!$D$11*(1-'Process Flow Mass Balance'!$J$31) | K36: =1-'Process Flow Mass Balance'!$D$11*(1-'Process Flow Mass Balance'!$K$31) | L36: =1-'Process Flow Mass Balance'!$D$11*(1-'Process Flow Mass Balance'!$L$31) | M36: =1-'Process Flow Mass Balance'!$D$11*(1-'Process Flow Mass Balance'!$M$31) | N36: =1-'Process Flow Mass Balance'!$D$11*(1-'Process Flow Mass Balance'!$N$31) | O36: =1-'Process Flow Mass Balance'!$D$11*(1-'Process Flow Mass Balance'!$O$31) | P36: =1-'Process Flow Mass Balance'!$D$11*(1-'Process Flow Mass Balance'!$P$31)
B37: Chlorine Contact (CT) | C37: 0 | D37: 0 | E37: 0 | F37: 0 | G37: 0 | H37: 0 | I37: 0 | J37: 0 | K37: 0 | L37: 0 | M37: 0.5 | N37: 0 | O37: 0 | P37: 0
B39: 4. Chemical dosing (mg/L of node inflow; negative = consumed)
B40: Process step | C40: EC | D40: TDS | E40: SiO₂ | F40: Na⁺ | G40: Ca²⁺ | H40: Mg²⁺ | I40: Cl⁻ | J40: PO₄³⁻ | K40: SO₄²⁻ | L40: Alk (CaCO₃) | M40: Free Cl₂ | N40: TSS | O40: BOD₅ | P40: COD
B41: Raw Water Intake | C41: 0 | D41: 0 | E41: 0 | F41: 0 | G41: 0 | H41: 0 | I41: 0 | J41: 0 | K41: 0 | L41: 0 | M41: 0 | N41: 0 | O41: 0 | P41: 0
B42: Coagulation / Flocculation / Sedimentation | C42: 6 | D42: 4 | E42: 0 | F42: 0 | G42: 0 | H42: 0 | I42: 0 | J42: 0 | K42: 4.85 | L42: -5 | M42: 0 | N42: 0 | O42: 0 | P42: 0
B43: Multi-Media Filtration | C43: 0 | D43: 0 | E43: 0 | F43: 0 | G43: 0 | H43: 0 | I43: 0 | J43: 0 | K43: 0 | L43: 0 | M43: 0 | N43: 0 | O43: 0 | P43: 0
B44: Ultrafiltration | C44: 0 | D44: 0 | E44: 0 | F44: 0 | G44: 0 | H44: 0 | I44: 0 | J44: 0 | K44: 0 | L44: 0 | M44: 0 | N44: 0 | O44: 0 | P44: 0
B45: RO / IX Demineralization | C45: 0 | D45: 0 | E45: 0 | F45: 0 | G45: 0 | H45: 0 | I45: 0 | J45: 0 | K45: 0 | L45: 0 | M45: 0 | N45: 0 | O45: 0 | P45: 0
B46: Chlorine Contact (CT) | C46: 4 | D46: 2.5 | E46: 0 | F46: 1 | G46: 0 | H46: 0 | I46: 1.5 | J46: 0 | K46: 0 | L46: 0 | M46: 1.5 | N46: 0 | O46: 0 | P46: 0
...

Sheet Cooling Tower & Corrugated Fill
B1: Cooling Tower Heat Balance & Corrugated Fill Simulation
B2: Q = ṁ·cp·ΔT · Tower Load = Q(1 + 1/COP) · E = TL/(970×8.34) · B = (E − (N−1)D)/(N·k − 1 + Y)
B5: 1. Shared design inputs
B6: Other heat to chilled water (fraction of IT) | C6: 0.05 | D6: -
B7: Chilled-water ΔT | C7: 12 | D7: °F
B8: Chiller COP at reference CWST | C8: 5.5 | D8: -
B9: Reference condenser-water supply temp | C9: 85 | D9: °F
B10: COP sensitivity per °F colder CWST | C10: 0.02 | D10: 1/°F | E10: Screening ~2 %/°F
B11: Non-cooling PUE overhead | C11: 0.08 | D11: -
B12: Tower range (hot − cold) | C12: 10 | D12: °F
B13: Water/air mass ratio L/G | C13: 1.2 | D13: -
B14: Barometric pressure | C14: 101.325 | D14: kPa
B15: Minimum CoC | C15: 1.2 | D15: cycles
B16: Max recirculating LSI (inhibitor program) | C16: 2.5 | D16: -
B17: Recirculating free-chlorine residual | C17: 0.5 | D17: mg/L
B18: Silica blowdown alert | C18: 150 | D18: mg/L
B19: Blowdown-recovery RO recovery Y | C19: 0.7 | D19: -
B20: LEED max Ca (as CaCO3) | C20: 1000 | D20: ppm | E20: LEED v4 WE Cooling Tower Water Use, Table 1
B21: LEED max alkalinity | C21: 1000 | D21: ppm | E21: LEED v4 WE Cooling Tower Water Use, Table 1
B22: LEED max SiO₂ | C22: 100 | D22: ppm | E22: LEED v4 WE Cooling Tower Water Use, Table 1
B23: LEED max chloride | C23: 250 | D23: ppm | E23: LEED v4 WE Cooling Tower Water Use, Table 1
B24: LEED max conductivity | C24: 2000 | D24: µS/cm | E24: LEED v4 WE Cooling Tower Water Use, Table 1
B25: Fill model c0 (KaV/L at reference) | C25: 1.2 | D25: - | E25: Screening calibration
B26: Reference SSA | C26: 150 | D26: m²/m³
B27: Reference fill height | C27: 1.2 | D27: m
B28: KaV/L exponent on L/G (n) | C28: 0.6 | D28: -
B29: Flute-angle thermal exponent | C29: 0.15 | D29: -
B31: 2. Scenario inputs — fill, drift eliminator, chemistry
B32: Parameter | C32: Current Baseline | D32: Corrugated Fill + High CoC | E32: Unit | F32: Note
B33: Fill / eliminator description | C33: Legacy offset film fill + blade eliminator | D33: Cross-fluted corrugated fill + cellular HE eliminator
B34: Specific surface area (SSA) | C34: 150 | D34: 226 | E34: m²/m³
B35: Flute angle | C35: 30 | D35: 60 | E35: °
B36: Sheet thickness | C36: 0.25 | D36: 0.38 | E36: mm
B37: Fill height | C37: 1 | D37: 1.2 | E37: m
B38: Drift fraction of recirculation | C38: 0.002 | D38: 1e-05 | E38: - | F38: 0.20 % → 0.001 % with HE eliminator
B39: Drift eliminator pressure drop | C39: 10 | D39: 20 | E39: Pa
B40: Recirculating pH | C40: 8.3 | D40: 8.4 | E40: -
B41: Target CoC (from Dashboard) | C41: ='Dashboard'!$C$15 | D41: ='Dashboard'!$D$15 | E41: cycles
B42: Blowdown recovery on (from Dashboard) | C42: ='Dashboard'!$C$16 | D42: ='Dashboard'!$D$16 | E42: -
B44: 3. Heat balance
...

Sheet Pumping & Fan Hydraulics
B1: Pumping & Induced-Draft Fan Hydraulics
B2: WHP = Q·TDH/3960 · BHP = WHP/η_h · kW = BHP·0.7457/(η_m·η_e) · N = ROUNDUP(Q/Q_BEP) · POR 0.7–1.2 Q_BEP
B5: 1. Fan & fill air-side inputs
B6: Tower water loading | C6: 6 | D6: gpm/ft²
B7: Exhaust air specific volume | C7: 14 | D7: ft³/lb
B8: Air density | C8: 1.15 | D8: kg/m³
B9: Other static pressure (louvers, plenum, exit) | C9: 60 | D9: Pa
B10: Fan efficiency | C10: 0.75 | D10: -
B11: Fan motor efficiency | C11: 0.94 | D11: -
B12: Fill ΔP coefficient c | C12: 0.06 | D12: - | E12: Screening calibration
B13: Fill ΔP flute-angle exponent | C13: 0.5 | D13: -
B15: 2. Induced-draft fan energy
B16: Parameter | C16: Current Baseline | D16: Corrugated Fill + High CoC | E16: Unit | F16: Formula
B17: Tower plan area | C17: ='Cooling Tower & Corrugated Fill'!$C$58/'Pumping & Fan Hydraulics'!$C$6/10.7639 | D17: ='Cooling Tower & Corrugated Fill'!$D$58/'Pumping & Fan Hydraulics'!$C$6/10.7639 | E17: m² | F17: Q_recirc / loading
B18: Air mass flow G = L/(L/G) | C18: ='Cooling Tower & Corrugated Fill'!$C$58*8.34*60/'Cooling Tower & Corrugated Fill'!$C$13 | D18: ='Cooling Tower & Corrugated Fill'!$D$58*8.34*60/'Cooling Tower & Corrugated Fill'!$C$13 | E18: lb/hr
B19: Airflow | C19: ='Pumping & Fan Hydraulics'!$C$18*'Pumping & Fan Hydraulics'!$C$7/60 | D19: ='Pumping & Fan Hydraulics'!$D$18*'Pumping & Fan Hydraulics'!$C$7/60 | E19: cfm
B20: Airflow | C20: ='Pumping & Fan Hydraulics'!$C$19*0.0283168/60 | D20: ='Pumping & Fan Hydraulics'!$D$19*0.0283168/60 | E20: m³/s
B21: Fill face velocity | C21: ='Pumping & Fan Hydraulics'!$C$20/'Pumping & Fan Hydraulics'!$C$17 | D21: ='Pumping & Fan Hydraulics'!$D$20/'Pumping & Fan Hydraulics'!$D$17 | E21: m/s
B22: Fill open area ε = 1 − SSA·t/2 | C22: =1-'Cooling Tower & Corrugated Fill'!$C$34*'Cooling Tower & Corrugated Fill'!$C$36/1000/2 | D22: =1-'Cooling Tower & Corrugated Fill'!$D$34*'Cooling Tower & Corrugated Fill'!$D$36/1000/2 | E22: -
B23: Fill ΔP = c·SSA·H·½ρv²·(θ/30)^b/ε² | C23: ='Pumping & Fan Hydraulics'!$C$12*'Cooling Tower & Corrugated Fill'!$C$34*'Cooling Tower & Corrugated Fill'!$C$37*0.5*'Pumping & Fan Hydraulics'!$C$8*'Pumping & Fan Hydraulics'!$C$21^2*('Cooling Tower & Corrugated Fill'!$C$35/30)^'Pumping & Fan Hydraulics'!$C$13/'Pumping & Fan Hydraulics'!$C$22^2 | D23: ='Pumping & Fan Hydraulics'!$C$12*'Cooling Tower & Corrugated Fill'!$D$34*'Cooling Tower & Corrugated Fill'!$D$37*0.5*'Pumping & Fan Hydraulics'!$C$8*'Pumping & Fan Hydraulics'!$D$21^2*('Cooling Tower & Corrugated Fill'!$D$35/30)^'Pumping & Fan Hydraulics'!$C$13/'Pumping & Fan Hydraulics'!$D$22^2 | E23: Pa
B24: Total static pressure | C24: ='Pumping & Fan Hydraulics'!$C$23+'Cooling Tower & Corrugated Fill'!$C$39+'Pumping & Fan Hydraulics'!$C$9 | D24: ='Pumping & Fan Hydraulics'!$D$23+'Cooling Tower & Corrugated Fill'!$D$39+'Pumping & Fan Hydraulics'!$C$9 | E24: Pa
B25: Total static pressure | C25: ='Pumping & Fan Hydraulics'!$C$24/249.089 | D25: ='Pumping & Fan Hydraulics'!$D$24/249.089 | E25: in. w.g.
B26: IDF fan power = V·ΔP/(η_f·η_m) | C26: ='Pumping & Fan Hydraulics'!$C$20*'Pumping & Fan Hydraulics'!$C$24/('Pumping & Fan Hydraulics'!$C$10*'Pumping & Fan Hydraulics'!$C$11)/1000 | D26: ='Pumping & Fan Hydraulics'!$D$20*'Pumping & Fan Hydraulics'!$D$24/('Pumping & Fan Hydraulics'!$C$10*'Pumping & Fan Hydraulics'!$C$11)/1000 | E26: kW
B28: 3. Pump stations (both scenarios)
B29: Pump station | C29: Scenario | D29: Flow Q (gpm) | E29: TDH (ft) | F29: Q_BEP (gpm) | G29: η hydraulic | H29: η mechanical | I29: η electrical | J29: N = ROUNDUP(Q/Q_BEP) | K29: Q per pump | L29: POR min | M29: POR max | N29: In POR? | O29: WHP | P29: BHP | Q29: kW
B30: Chilled-Water Pumps | C30: Baseline | D30: ='Cooling Tower & Corrugated Fill'!$C$45/(8.34*60*'Cooling Tower & Corrugated Fill'!$C$7) | E30: 120 | F30: 3000 | G30: 0.82 | H30: 0.98 | I30: 0.95 | J30: =MAX(1,ROUNDUP(D30/F30,0)) | K30: =D30/J30 | L30: =0.7*F30 | M30: =1.2*F30 | N30: =IF(AND(K30>=L30,K30<=M30),"✅ In POR","❌ Outside") | O30: =D30*E30/3960 | P30: =O30/G30 | Q30: =P30*0.7457/(H30*I30)
B31: Chilled-Water Pumps | C31: Optimized | D31: ='Cooling Tower & Corrugated Fill'!$D$45/(8.34*60*'Cooling Tower & Corrugated Fill'!$C$7) | E31: ='Pumping & Fan Hydraulics'!$E$30 | F31: ='Pumping & Fan Hydraulics'!$F$30 | G31: ='Pumping & Fan Hydraulics'!$G$30 | H31: ='Pumping & Fan Hydraulics'!$H$30 | I31: ='Pumping & Fan Hydraulics'!$I$30 | J31: =MAX(1,ROUNDUP(D31/F31,0)) | K31: =D31/J31 | L31: =0.7*F31 | M31: =1.2*F31 | N31: =IF(AND(K31>=L31,K31<=M31),"✅ In POR","❌ Outside") | O31: =D31*E31/3960 | P31: =O31/G31 | Q31: =P31*0.7457/(H31*I31)
B32: Condenser-Water Pumps | C32: Baseline | D32: ='Cooling Tower & Corrugated Fill'!$C$58 | E32: 80 | F32: 4000 | G32: 0.84 | H32: 0.98 | I32: 0.95 | J32: =MAX(1,ROUNDUP(D32/F32,0)) | K32: =D32/J32 | L32: =0.7*F32 | M32: =1.2*F32 | N32: =IF(AND(K32>=L32,K32<=M32),"✅ In POR","❌ Outside") | O32: =D32*E32/3960 | P32: =O32/G32 | Q32: =P32*0.7457/(H32*I32)
B33: Condenser-Water Pumps | C33: Optimized | D33: ='Cooling Tower & Corrugated Fill'!$D$58 | E33: ='Pumping & Fan Hydraulics'!$E$32 | F33: ='Pumping & Fan Hydraulics'!$F$32 | G33: ='Pumping & Fan Hydraulics'!$G$32 | H33: ='Pumping & Fan Hydraulics'!$H$32 | I33: ='Pumping & Fan Hydraulics'!$I$32 | J33: =MAX(1,ROUNDUP(D33/F33,0)) | K33: =D33/J33 | L33: =0.7*F33 | M33: =1.2*F33 | N33: =IF(AND(K33>=L33,K33<=M33),"✅ In POR","❌ Outside") | O33: =D33*E33/3960 | P33: =O33/G33 | Q33: =P33*0.7457/(H33*I33)
B34: Raw/Makeup Water Pumps | C34: Baseline | D34: ='Cooling Tower & Corrugated Fill'!$C$86/1440 | E34: 150 | F34: 300 | G34: 0.7 | H34: 0.98 | I34: 0.92 | J34: =MAX(1,ROUNDUP(D34/F34,0)) | K34: =D34/J34 | L34: =0.7*F34 | M34: =1.2*F34 | N34: =IF(AND(K34>=L34,K34<=M34),"✅ In POR","❌ Outside") | O34: =D34*E34/3960 | P34: =O34/G34 | Q34: =P34*0.7457/(H34*I34)
B35: Raw/Makeup Water Pumps | C35: Optimized | D35: ='Cooling Tower & Corrugated Fill'!$D$86/1440 | E35: ='Pumping & Fan Hydraulics'!$E$34 | F35: ='Pumping & Fan Hydraulics'!$F$34 | G35: ='Pumping & Fan Hydraulics'!$G$34 | H35: ='Pumping & Fan Hydraulics'!$H$34 | I35: ='Pumping & Fan Hydraulics'!$I$34 | J35: =MAX(1,ROUNDUP(D35/F35,0)) | K35: =D35/J35 | L35: =0.7*F35 | M35: =1.2*F35 | N35: =IF(AND(K35>=L35,K35<=M35),"✅ In POR","❌ Outside") | O35: =D35*E35/3960 | P35: =O35/G35 | Q35: =P35*0.7457/(H35*I35)
B38: 4. Plant power summary
B39: Component | C39: Current Baseline | D39: Corrugated Fill + High CoC | E39: Unit
B40: Chiller compressors | C40: ='Cooling Tower & Corrugated Fill'!$C$55 | D40: ='Cooling Tower & Corrugated Fill'!$D$55 | E40: kW
B41: Tower fans | C41: ='Pumping & Fan Hydraulics'!$C$26 | D41: ='Pumping & Fan Hydraulics'!$D$26 | E41: kW
B42: Chilled-water pumps | C42: ='Pumping & Fan Hydraulics'!$Q$30 | D42: ='Pumping & Fan Hydraulics'!$Q$31 | E42: kW
B43: Condenser-water pumps | C43: ='Pumping & Fan Hydraulics'!$Q$32 | D43: ='Pumping & Fan Hydraulics'!$Q$33 | E43: kW
B44: Raw/makeup water pumps | C44: ='Pumping & Fan Hydraulics'!$Q$34 | D44: ='Pumping & Fan Hydraulics'!$Q$35 | E44: kW
B45: BD-RO energy | C45: =IF('Cooling Tower & Corrugated Fill'!$C$42=1,(0.3+0.1*'Cooling Tower & Corrugated Fill'!$F$96/1000)*1000*0.00378541*'Cooling Tower & Corrugated Fill'!$C$80/1000,0) | D45: =IF('Cooling Tower & Corrugated Fill'!$D$42=1,(0.3+0.1*'Cooling Tower & Corrugated Fill'!$K$96/1000)*1000*0.00378541*'Cooling Tower & Corrugated Fill'!$D$80/1000,0) | E45: kWh/d
B46: Water treatment (train + BD-RO) | C46: =('Process Flow Mass Balance'!$C$15*'Cooling Tower & Corrugated Fill'!$C$86+'Pumping & Fan Hydraulics'!$C$45)/24 | D46: =('Process Flow Mass Balance'!$C$15*'Cooling Tower & Corrugated Fill'!$D$86+'Pumping & Fan Hydraulics'!$D$45)/24 | E46: kW
...

Sheet Disinfection & Microbial Risk
B1: Disinfection CT & Quantitative Microbial Risk Assessment
B2: CT = C·T10 · T10 = TDT·BF · LRT = LOG(C_in/C_target) · Pd = 1 − (1 + d/β)^−α · Py = 1 − (1 − Pd)^n
B5: 1. Chlorine contact inputs
B6: Contact tank operating volume | C6: 100000 | D6: gal
B7: Peak flow factor | C7: 1.5 | D7: -
B8: Baffling factor BF (0.1 unbaffled – 0.9 plug flow) | C8: 0.3 | D8: -
B9: Water temperature | C9: 20 | D9: °C
B10: Free chlorine residual (Mass Balance outlet) | C10: ='Process Flow Mass Balance'!$AH$55 | D10: mg/L
B12: 2. CT required lookup (free chlorine, SWTR Guidance Manual)
B13: Temp (°C) | C13: CT 4-log virus | E13: Temp (°C) | F13: CT 3-log Giardia (pH 7)
B14: 0.5 | C14: 12 | E14: 5 | F14: 149
B15: 5 | C15: 8 | E15: 10 | F15: 112
B16: 10 | C16: 6 | E16: 15 | F16: 75
B17: 15 | C17: 4 | E17: 20 | F17: 56
B18: 20 | C18: 3 | E18: 25 | F18: 37
B19: 25 | C19: 2
B22: 3. CT verification
B23: Parameter | C23: Current Baseline | D23: Corrugated Fill + High CoC | E23: Unit | F23: Formula
B24: Contact flow (train) | C24: ='Cooling Tower & Corrugated Fill'!$C$86*'Process Flow Mass Balance'!$K$12 | D24: ='Cooling Tower & Corrugated Fill'!$D$86*'Process Flow Mass Balance'!$K$12 | E24: gpd
B25: Peak flow Q_peak | C25: ='Disinfection & Microbial Risk'!$C$24/1440*'Disinfection & Microbial Risk'!$C$7 | D25: ='Disinfection & Microbial Risk'!$D$24/1440*'Disinfection & Microbial Risk'!$C$7 | E25: gpm
B26: Total detention time TDT = V/Q_peak | C26: ='Disinfection & Microbial Risk'!$C$6/'Disinfection & Microbial Risk'!$C$25 | D26: ='Disinfection & Microbial Risk'!$C$6/'Disinfection & Microbial Risk'!$D$25 | E26: min
B27: T10 = TDT × BF | C27: ='Disinfection & Microbial Risk'!$C$26*'Disinfection & Microbial Risk'!$C$8 | D27: ='Disinfection & Microbial Risk'!$D$26*'Disinfection & Microbial Risk'!$C$8 | E27: min
B28: CT = C × T10 | C28: ='Disinfection & Microbial Risk'!$C$10*'Disinfection & Microbial Risk'!$C$27 | D28: ='Disinfection & Microbial Risk'!$C$10*'Disinfection & Microbial Risk'!$D$27 | E28: mg·min/L
B29: CT required 4-log virus | C29: =(INDEX('Disinfection & Microbial Risk'!$C$14:$C$19,MATCH(MAX(MIN('Disinfection & Microbial Risk'!$C$9,INDEX('Disinfection & Microbial Risk'!$B$14:$B$19,6)),INDEX('Disinfection & Microbial Risk'!$B$14:$B$19,1)),'Disinfection & Microbial Risk'!$B$14:$B$19,1))+(INDEX('Disinfection & Microbial Risk'!$C$14:$C$19,MIN(MATCH(MAX(MIN('Disinfection & Microbial Risk'!$C$9,INDEX('Disinfection & Microbial Risk'!$B$14:$B$19,6)),INDEX('Disinfection & Microbial Risk'!$B$14:$B$19,1)),'Disinfection & Microbial Risk'!$B$14:$B$19,1)+1,6))-INDEX('Disinfection & Microbial Risk'!$C$14:$C$19,MATCH(MAX(MIN('Disinfection & Microbial Risk'!$C$9,INDEX('Disinfection & Microbial Risk'!$B$14:$B$19,6)),INDEX('Disinfection & Microbial Risk'!$B$14:$B$19,1)),'Disinfection & Microbial Risk'!$B$14:$B$19,1)))*(MAX(MIN('Disinfection & Microbial Risk'!$C$9,INDEX('Disinfection & Microbial Risk'!$B$14:$B$19,6)),INDEX('Disinfection & Microbial Risk'!$B$14:$B$19,1))-INDEX('Disinfection & Microbial Risk'!$B$14:$B$19,MATCH(MAX(MIN('Disinfection & Microbial Risk'!$C$9,INDEX('Disinfection & Microbial Risk'!$B$14:$B$19,6)),INDEX('Disinfection & Microbial Risk'!$B$14:$B$19,1)),'Disinfection & Microbial Risk'!$B$14:$B$19,1)))/MAX(INDEX('Disinfection & Microbial Risk'!$B$14:$B$19,MIN(MATCH(MAX(MIN('Disinfection & Microbial Risk'!$C$9,INDEX('Disinfection & Microbial Risk'!$B$14:$B$19,6)),INDEX('Disinfection & Microbial Risk'!$B$14:$B$19,1)),'Disinfection & Microbial Risk'!$B$14:$B$19,1)+1,6))-INDEX('Disinfection & Microbial Risk'!$B$14:$B$19,MATCH(MAX(MIN('Disinfection & Microbial Risk'!$C$9,INDEX('Disinfection & Microbial Risk'!$B$14:$B$19,6)),INDEX('Disinfection & Microbial Risk'!$B$14:$B$19,1)),'Disinfection & Microbial Risk'!$B$14:$B$19,1)),0.000000001)) | D29: =(INDEX('Disinfection & Microbial Risk'!$C$14:$C$19,MATCH(MAX(MIN('Disinfection & Microbial Risk'!$C$9,INDEX('Disinfection & Microbial Risk'!$B$14:$B$19,6)),INDEX('Disinfection & Microbial Risk'!$B$14:$B$19,1)),'Disinfection & Microbial Risk'!$B$14:$B$19,1))+(INDEX('Disinfection & Microbial Risk'!$C$14:$C$19,MIN(MATCH(MAX(MIN('Disinfection & Microbial Risk'!$C$9,INDEX('Disinfection & Microbial Risk'!$B$14:$B$19,6)),INDEX('Disinfection & Microbial Risk'!$B$14:$B$19,1)),'Disinfection & Microbial Risk'!$B$14:$B$19,1)+1,6))-INDEX('Disinfection & Microbial Risk'!$C$14:$C$19,MATCH(MAX(MIN('Disinfection & Microbial Risk'!$C$9,INDEX('Disinfection & Microbial Risk'!$B$14:$B$19,6)),INDEX('Disinfection & Microbial Risk'!$B$14:$B$19,1)),'Disinfection & Microbial Risk'!$B$14:$B$19,1)))*(MAX(MIN('Disinfection & Microbial Risk'!$C$9,INDEX('Disinfection & Microbial Risk'!$B$14:$B$19,6)),INDEX('Disinfection & Microbial Risk'!$B$14:$B$19,1))-INDEX('Disinfection & Microbial Risk'!$B$14:$B$19,MATCH(MAX(MIN('Disinfection & Microbial Risk'!$C$9,INDEX('Disinfection & Microbial Risk'!$B$14:$B$19,6)),INDEX('Disinfection & Microbial Risk'!$B$14:$B$19,1)),'Disinfection & Microbial Risk'!$B$14:$B$19,1)))/MAX(INDEX('Disinfection & Microbial Risk'!$B$14:$B$19,MIN(MATCH(MAX(MIN('Disinfection & Microbial Risk'!$C$9,INDEX('Disinfection & Microbial Risk'!$B$14:$B$19,6)),INDEX('Disinfection & Microbial Risk'!$B$14:$B$19,1)),'Disinfection & Microbial Risk'!$B$14:$B$19,1)+1,6))-INDEX('Disinfection & Microbial Risk'!$B$14:$B$19,MATCH(MAX(MIN('Disinfection & Microbial Risk'!$C$9,INDEX('Disinfection & Microbial Risk'!$B$14:$B$19,6)),INDEX('Disinfection & Microbial Risk'!$B$14:$B$19,1)),'Disinfection & Microbial Risk'!$B$14:$B$19,1)),0.000000001)) | E29: mg·min/L
B30: CT required 3-log Giardia | C30: =(INDEX('Disinfection & Microbial Risk'!$F$14:$F$18,MATCH(MAX(MIN('Disinfection & Microbial Risk'!$C$9,INDEX('Disinfection & Microbial Risk'!$E$14:$E$18,5)),INDEX('Disinfection & Microbial Risk'!$E$14:$E$18,1)),'Disinfection & Microbial Risk'!$E$14:$E$18,1))+(INDEX('Disinfection & Microbial Risk'!$F$14:$F$18,MIN(MATCH(MAX(MIN('Disinfection & Microbial Risk'!$C$9,INDEX('Disinfection & Microbial Risk'!$E$14:$E$18,5)),INDEX('Disinfection & Microbial Risk'!$E$14:$E$18,1)),'Disinfection & Microbial Risk'!$E$14:$E$18,1)+1,5))-INDEX('Disinfection & Microbial Risk'!$F$14:$F$18,MATCH(MAX(MIN('Disinfection & Microbial Risk'!$C$9,INDEX('Disinfection & Microbial Risk'!$E$14:$E$18,5)),INDEX('Disinfection & Microbial Risk'!$E$14:$E$18,1)),'Disinfection & Microbial Risk'!$E$14:$E$18,1)))*(MAX(MIN('Disinfection & Microbial Risk'!$C$9,INDEX('Disinfection & Microbial Risk'!$E$14:$E$18,5)),INDEX('Disinfection & Microbial Risk'!$E$14:$E$18,1))-INDEX('Disinfection & Microbial Risk'!$E$14:$E$18,MATCH(MAX(MIN('Disinfection & Microbial Risk'!$C$9,INDEX('Disinfection & Microbial Risk'!$E$14:$E$18,5)),INDEX('Disinfection & Microbial Risk'!$E$14:$E$18,1)),'Disinfection & Microbial Risk'!$E$14:$E$18,1)))/MAX(INDEX('Disinfection & Microbial Risk'!$E$14:$E$18,MIN(MATCH(MAX(MIN('Disinfection & Microbial Risk'!$C$9,INDEX('Disinfection & Microbial Risk'!$E$14:$E$18,5)),INDEX('Disinfection & Microbial Risk'!$E$14:$E$18,1)),'Disinfection & Microbial Risk'!$E$14:$E$18,1)+1,5))-INDEX('Disinfection & Microbial Risk'!$E$14:$E$18,MATCH(MAX(MIN('Disinfection & Microbial Risk'!$C$9,INDEX('Disinfection & Microbial Risk'!$E$14:$E$18,5)),INDEX('Disinfection & Microbial Risk'!$E$14:$E$18,1)),'Disinfection & Microbial Risk'!$E$14:$E$18,1)),0.000000001)) | D30: =(INDEX('Disinfection & Microbial Risk'!$F$14:$F$18,MATCH(MAX(MIN('Disinfection & Microbial Risk'!$C$9,INDEX('Disinfection & Microbial Risk'!$E$14:$E$18,5)),INDEX('Disinfection & Microbial Risk'!$E$14:$E$18,1)),'Disinfection & Microbial Risk'!$E$14:$E$18,1))+(INDEX('Disinfection & Microbial Risk'!$F$14:$F$18,MIN(MATCH(MAX(MIN('Disinfection & Microbial Risk'!$C$9,INDEX('Disinfection & Microbial Risk'!$E$14:$E$18,5)),INDEX('Disinfection & Microbial Risk'!$E$14:$E$18,1)),'Disinfection & Microbial Risk'!$E$14:$E$18,1)+1,5))-INDEX('Disinfection & Microbial Risk'!$F$14:$F$18,MATCH(MAX(MIN('Disinfection & Microbial Risk'!$C$9,INDEX('Disinfection & Microbial Risk'!$E$14:$E$18,5)),INDEX('Disinfection & Microbial Risk'!$E$14:$E$18,1)),'Disinfection & Microbial Risk'!$E$14:$E$18,1)))*(MAX(MIN('Disinfection & Microbial Risk'!$C$9,INDEX('Disinfection & Microbial Risk'!$E$14:$E$18,5)),INDEX('Disinfection & Microbial Risk'!$E$14:$E$18,1))-INDEX('Disinfection & Microbial Risk'!$E$14:$E$18,MATCH(MAX(MIN('Disinfection & Microbial Risk'!$C$9,INDEX('Disinfection & Microbial Risk'!$E$14:$E$18,5)),INDEX('Disinfection & Microbial Risk'!$E$14:$E$18,1)),'Disinfection & Microbial Risk'!$E$14:$E$18,1)))/MAX(INDEX('Disinfection & Microbial Risk'!$E$14:$E$18,MIN(MATCH(MAX(MIN('Disinfection & Microbial Risk'!$C$9,INDEX('Disinfection & Microbial Risk'!$E$14:$E$18,5)),INDEX('Disinfection & Microbial Risk'!$E$14:$E$18,1)),'Disinfection & Microbial Risk'!$E$14:$E$18,1)+1,5))-INDEX('Disinfection & Microbial Risk'!$E$14:$E$18,MATCH(MAX(MIN('Disinfection & Microbial Risk'!$C$9,INDEX('Disinfection & Microbial Risk'!$E$14:$E$18,5)),INDEX('Disinfection & Microbial Risk'!$E$14:$E$18,1)),'Disinfection & Microbial Risk'!$E$14:$E$18,1)),0.000000001)) | E30: mg·min/L
B31: Virus inactivation credit = MIN(4, 4·CT/CTreq) | C31: ='Process Flow Mass Balance'!$C$12*MIN(4,4*'Disinfection & Microbial Risk'!$C$28/'Disinfection & Microbial Risk'!$C$29) | D31: ='Process Flow Mass Balance'!$C$12*MIN(4,4*'Disinfection & Microbial Risk'!$D$28/'Disinfection & Microbial Risk'!$D$29) | E31: log
B32: Giardia inactivation credit = MIN(3, 3·CT/CTreq) | C32: ='Process Flow Mass Balance'!$C$12*MIN(3,3*'Disinfection & Microbial Risk'!$C$28/'Disinfection & Microbial Risk'!$C$30) | D32: ='Process Flow Mass Balance'!$C$12*MIN(3,3*'Disinfection & Microbial Risk'!$D$28/'Disinfection & Microbial Risk'!$D$30) | E32: log
B33: 4-log virus achieved? | C33: =IF('Disinfection & Microbial Risk'!$C$31>=4,"✅ Achieved","❌ Not achieved") | D33: =IF('Disinfection & Microbial Risk'!$D$31>=4,"✅ Achieved","❌ Not achieved")
B35: 4. Physical log-removal credits (enabled nodes, Mass Balance sheet)
B36: Virus LRV (Σ on × LRV) | C36: =SUMPRODUCT('Process Flow Mass Balance'!$C$7:$C$12,'Process Flow Mass Balance'!$F$7:$F$12) | D36: log
B37: Protozoa LRV | C37: =SUMPRODUCT('Process Flow Mass Balance'!$C$7:$C$12,'Process Flow Mass Balance'!$G$7:$G$12) | D37: log
B38: Bacteria LRV | C38: =SUMPRODUCT('Process Flow Mass Balance'!$C$7:$C$12,'Process Flow Mass Balance'!$H$7:$H$12) | D38: log
B40: 5. Ingestion QMRA (worker exposure to cooling water)
B41: Target annual risk Py | C41: 0.0001 | D41: per yr
B42: Ingested volume per event | C42: 1e-05 | D42: L | E42: WERF Table 3-1
B43: Events per year n | C43: 250 | D43: 1/yr
B44: Allowable per-event risk Pd = 1 − (1 − Py)^(1/n) | C44: =1-(1-'Disinfection & Microbial Risk'!$C$41)^(1/'Disinfection & Microbial Risk'!$C$43) | D44: -
B46: Pathogen | C46: Model | D46: α | E46: β | F46: r | G46: LRV class | H46: C source | I46: Allowable dose d | J46: C target | K46: LRT required | L46: LRV Base | M46: Py Base | N46: Check Base | O46: LRV Opt | P46: Py Opt | Q46: Check Opt
B47: Rotavirus | C47: beta_poisson | D47: 0.253 | E47: 0.422 | F47: 0 | G47: virus | H47: ='Source Library'!$J$22 | I47: =IF(C47="beta_poisson",E47*((1-'Disinfection & Microbial Risk'!$C$44)^(-1/D47)-1),-LN(1-'Disinfection & Microbial Risk'!$C$44)/F47) | J47: =I47/'Disinfection & Microbial Risk'!$C$42 | K47: =IF(H47>J47,LOG(H47/J47),0) | L47: ='Disinfection & Microbial Risk'!$C$36+'Disinfection & Microbial Risk'!$C$31 | M47: =1-(1-IF(C47="beta_poisson",1-(1+(H47/10^L47*'Disinfection & Microbial Risk'!$C$42)/E47)^(-D47),1-EXP(-F47*(H47/10^L47*'Disinfection & Microbial Risk'!$C$42))))^'Disinfection & Microbial Risk'!$C$43 | N47: =IF(M47<='Disinfection & Microbial Risk'!$C$41,"✅","❌") | O47: ='Disinfection & Microbial Risk'!$C$36+'Disinfection & Microbial Risk'!$D$31 | P47: =1-(1-IF(C47="beta_poisson",1-(1+(H47/10^O47*'Disinfection & Microbial Risk'!$C$42)/E47)^(-D47),1-EXP(-F47*(H47/10^O47*'Disinfection & Microbial Risk'!$C$42))))^'Disinfection & Microbial Risk'!$C$43 | Q47: =IF(P47<='Disinfection & Microbial Risk'!$C$41,"✅","❌")
B48: Giardia | C48: exponential | D48: 0 | E48: 0 | F48: 0.0199 | G48: protozoa | H48: ='Source Library'!$J$23 | I48: =IF(C48="beta_poisson",E48*((1-'Disinfection & Microbial Risk'!$C$44)^(-1/D48)-1),-LN(1-'Disinfection & Microbial Risk'!$C$44)/F48) | J48: =I48/'Disinfection & Microbial Risk'!$C$42 | K48: =IF(H48>J48,LOG(H48/J48),0) | L48: ='Disinfection & Microbial Risk'!$C$37+'Disinfection & Microbial Risk'!$C$32 | M48: =1-(1-IF(C48="beta_poisson",1-(1+(H48/10^L48*'Disinfection & Microbial Risk'!$C$42)/E48)^(-D48),1-EXP(-F48*(H48/10^L48*'Disinfection & Microbial Risk'!$C$42))))^'Disinfection & Microbial Risk'!$C$43 | N48: =IF(M48<='Disinfection & Microbial Risk'!$C$41,"✅","❌") | O48: ='Disinfection & Microbial Risk'!$C$37+'Disinfection & Microbial Risk'!$D$32 | P48: =1-(1-IF(C48="beta_poisson",1-(1+(H48/10^O48*'Disinfection & Microbial Risk'!$C$42)/E48)^(-D48),1-EXP(-F48*(H48/10^O48*'Disinfection & Microbial Risk'!$C$42))))^'Disinfection & Microbial Risk'!$C$43 | Q48: =IF(P48<='Disinfection & Microbial Risk'!$C$41,"✅","❌")
...

Sheet Financial & LCC Analysis
B1: Financial & Lifecycle Cost Analysis (NYC DEP FY2022 tariffs)
B2: i = r_interest + r_inflation · PV = FV/(1+i)^n · NPV = Σ CF_t/(1+i)^t − CapEx · SPBT = CapEx / savings
B5: 1. Tariffs, prices & finance inputs
B6: Water rate | C6: 4.1 | D6: $/100 ft³ | E6: NYC DEP FY22 metered water
B7: Water rate | C7: ='Financial & LCC Analysis'!$C$6/748.052*1000 | D7: $/kgal
B8: Sewer charge multiplier | C8: 1.59 | D8: × water | E8: 159 % of water charge
B9: Sewer rate | C9: ='Financial & LCC Analysis'!$C$7*'Financial & LCC Analysis'!$C$8 | D9: $/kgal
B10: Cooling-tower sewer allowance (evaporation exempt) 1/0 | C10: 1 | D10: -
B11: Electricity | C11: 0.2 | D11: $/kWh
B12: Sodium hypochlorite (as Cl₂) | C12: 0.6 | D12: $/kg
B13: Alum | C13: 0.35 | D13: $/kg
B14: Scale/corrosion inhibitor | C14: 3 | D14: $/kg
B15: Sludge disposal | C15: 150 | D15: $/dry ton
B16: Alum sludge yield | C16: 0.26 | D16: kg/kg
B17: Tower biocide dose (per makeup) | C17: 2 | D17: mg/L
B18: Inhibitor held in recirculation | C18: 10 | D18: mg/L
B19: Grid emission factor | C19: 0.88 | D19: lb CO₂/kWh
B20: Social cost of carbon | C20: 142 | D20: $/t
B21: Hours per year | C21: 8760 | D21: h
B22: Operating days equivalent = hours/24 × utilization | C22: ='Financial & LCC Analysis'!$C$21/24*'Dashboard'!$C$10 | D22: d/yr
B23: Interest rate | C23: 0.04 | D23: -
B24: Inflation rate | C24: 0.03 | D24: -
B25: Discount rate i = interest + inflation | C25: ='Financial & LCC Analysis'!$C$23+'Financial & LCC Analysis'!$C$24 | D25: -
B26: Utility cost escalation | C26: 0.0276 | D26: - | E26: NYC water rate +2.76 % (FY22)
B27: Fill cost | C27: 350 | D27: $/m³
B28: Drift eliminator cost | C28: 120 | D28: $/m²
B29: Blowdown-recovery RO cost | C29: 2 | D29: $/gpd
B30: Installation factor | C30: 1.3 | D30: ×
B32: 2. Annual quantities
B33: Quantity | C33: Current Baseline | D33: Corrugated Fill + High CoC | E33: Unit
B34: Raw water intake | C34: ='Cooling Tower & Corrugated Fill'!$C$86*'Financial & LCC Analysis'!$C$22 | D34: ='Cooling Tower & Corrugated Fill'!$D$86*'Financial & LCC Analysis'!$C$22 | E34: gal/yr
B35: Sewer discharge | C35: ='Cooling Tower & Corrugated Fill'!$C$89*'Financial & LCC Analysis'!$C$22 | D35: ='Cooling Tower & Corrugated Fill'!$D$89*'Financial & LCC Analysis'!$C$22 | E35: gal/yr
B36: Electricity | C36: ='Pumping & Fan Hydraulics'!$C$47*'Financial & LCC Analysis'!$C$21*'Dashboard'!$C$10 | D36: ='Pumping & Fan Hydraulics'!$D$47*'Financial & LCC Analysis'!$C$21*'Dashboard'!$C$10 | E36: kWh/yr
B37: Alum | C37: ='Process Flow Mass Balance'!$C$8*'Process Flow Mass Balance'!$C$27*'Cooling Tower & Corrugated Fill'!$C$86*'Process Flow Mass Balance'!$K$8*3.78541/1000000*'Financial & LCC Analysis'!$C$22 | D37: ='Process Flow Mass Balance'!$C$8*'Process Flow Mass Balance'!$C$27*'Cooling Tower & Corrugated Fill'!$D$86*'Process Flow Mass Balance'!$K$8*3.78541/1000000*'Financial & LCC Analysis'!$C$22 | E37: kg/yr
B38: NaOCl (contact + tower biocide) | C38: =('Process Flow Mass Balance'!$C$12*'Process Flow Mass Balance'!$M$46*'Cooling Tower & Corrugated Fill'!$C$86*'Process Flow Mass Balance'!$K$12+'Financial & LCC Analysis'!$C$17*'Cooling Tower & Corrugated Fill'!$C$85)*3.78541/1000000*'Financial & LCC Analysis'!$C$22 | D38: =('Process Flow Mass Balance'!$C$12*'Process Flow Mass Balance'!$M$46*'Cooling Tower & Corrugated Fill'!$D$86*'Process Flow Mass Balance'!$K$12+'Financial & LCC Analysis'!$C$17*'Cooling Tower & Corrugated Fill'!$D$85)*3.78541/1000000*'Financial & LCC Analysis'!$C$22 | E38: kg/yr
B39: Inhibitor = C × (B + D) | C39: ='Financial & LCC Analysis'!$C$18*('Cooling Tower & Corrugated Fill'!$C$80+'Cooling Tower & Corrugated Fill'!$C$61)*3.78541/1000000*'Financial & LCC Analysis'!$C$22 | D39: ='Financial & LCC Analysis'!$C$18*('Cooling Tower & Corrugated Fill'!$D$80+'Cooling Tower & Corrugated Fill'!$D$61)*3.78541/1000000*'Financial & LCC Analysis'!$C$22 | E39: kg/yr
B40: Dry sludge | C40: =(SUM('Process Flow Mass Balance'!$AM$50:$AM$55)*'Cooling Tower & Corrugated Fill'!$C$86+'Financial & LCC Analysis'!$C$37/'Financial & LCC Analysis'!$C$22*'Financial & LCC Analysis'!$C$16)/907.185*'Financial & LCC Analysis'!$C$22 | D40: =(SUM('Process Flow Mass Balance'!$AM$50:$AM$55)*'Cooling Tower & Corrugated Fill'!$D$86+'Financial & LCC Analysis'!$D$37/'Financial & LCC Analysis'!$C$22*'Financial & LCC Analysis'!$C$16)/907.185*'Financial & LCC Analysis'!$C$22 | E40: dry t/yr
B41: CO₂e | C41: ='Financial & LCC Analysis'!$C$36*'Financial & LCC Analysis'!$C$19/2204.6 | D41: ='Financial & LCC Analysis'!$D$36*'Financial & LCC Analysis'!$C$19/2204.6 | E41: t/yr
B43: 3. Annual operating cost (year 1)
B44: Cost item | C44: Current Baseline | D44: Corrugated Fill + High CoC | E44: Unit
...

Sheet Source Library
B1: Source Library — Raw Water Quality Matrices
B2: Edit any yellow cell; the Dashboard source selector pulls the matching column.
B5: Baseline quality by source
B6: Parameter | C6: Unit | D6: Municipal Potable | E6: Sea Water | F6: River Water | G6: Groundwater | H6: MBR Permeate / Wastewater Reuse | I6: Rainwater (roof harvest) | J6: Selected source
B7: pH | C7: - | D7: 7.2 | E7: 8.1 | F7: 7.6 | G7: 7.3 | H7: 7 | I7: 6 | J7: =INDEX(D7:I7,MATCH('Dashboard'!$C$6,'Source Library'!$D$6:$I$6,0))
B8: EC | C8: µS/cm | D8: 110 | E8: 53000 | F8: 400 | G8: 700 | H8: 900 | I8: 20 | J8: =INDEX(D8:I8,MATCH('Dashboard'!$C$6,'Source Library'!$D$6:$I$6,0))
B9: TDS | C9: mg/L | D9: 65 | E9: 35000 | F9: 260 | G9: 455 | H9: 585 | I9: 13 | J9: =INDEX(D9:I9,MATCH('Dashboard'!$C$6,'Source Library'!$D$6:$I$6,0))
B10: SiO₂ | C10: mg/L | D10: 3.5 | E10: 2 | F10: 12 | G10: 30 | H10: 20 | I10: 0.5 | J10: =INDEX(D10:I10,MATCH('Dashboard'!$C$6,'Source Library'!$D$6:$I$6,0))
B11: Na⁺ | C11: mg/L | D11: 10 | E11: 10770 | F11: 20 | G11: 40 | H11: 90 | I11: 1 | J11: =INDEX(D11:I11,MATCH('Dashboard'!$C$6,'Source Library'!$D$6:$I$6,0))
B12: Ca²⁺ | C12: mg/L | D12: 7 | E12: 412 | F12: 40 | G12: 90 | H12: 50 | I12: 1 | J12: =INDEX(D12:I12,MATCH('Dashboard'!$C$6,'Source Library'!$D$6:$I$6,0))
B13: Mg²⁺ | C13: mg/L | D13: 1.5 | E13: 1290 | F13: 10 | G13: 25 | H13: 15 | I13: 0.3 | J13: =INDEX(D13:I13,MATCH('Dashboard'!$C$6,'Source Library'!$D$6:$I$6,0))
B14: Cl⁻ | C14: mg/L | D14: 15 | E14: 19350 | F14: 25 | G14: 50 | H14: 110 | I14: 2 | J14: =INDEX(D14:I14,MATCH('Dashboard'!$C$6,'Source Library'!$D$6:$I$6,0))
B15: PO₄³⁻ | C15: mg/L | D15: 2 | E15: 0.1 | F15: 0.3 | G15: 0.1 | H15: 4 | I15: 0.05 | J15: =INDEX(D15:I15,MATCH('Dashboard'!$C$6,'Source Library'!$D$6:$I$6,0))
B16: SO₄²⁻ | C16: mg/L | D16: 6 | E16: 2710 | F16: 40 | G16: 60 | H16: 70 | I16: 2 | J16: =INDEX(D16:I16,MATCH('Dashboard'!$C$6,'Source Library'!$D$6:$I$6,0))
B17: Alk (CaCO₃) | C17: mg/L | D17: 15 | E17: 116 | F17: 110 | G17: 250 | H17: 120 | I17: 5 | J17: =INDEX(D17:I17,MATCH('Dashboard'!$C$6,'Source Library'!$D$6:$I$6,0))
B18: Free Cl₂ | C18: mg/L | D18: 0.7 | E18: 0 | F18: 0 | G18: 0 | H18: 0 | I18: 0 | J18: =INDEX(D18:I18,MATCH('Dashboard'!$C$6,'Source Library'!$D$6:$I$6,0))
... B30: Recycled non-potable (LEED) 1/0 | C30: - | D30: 0 | E30: 0 | F30: 0 | G30: 0 | H30: 1 | I30: 1 | J30: =INDEX(D30:I30,MATCH('Dashboard'!$C$6,'Source Library'!$D$6:$I$6,0))

Sheet Merkel Solver
B1: Merkel Solver — required tower characteristic KaV/L vs cold-water temperature
B2: KaV/L = Range/4 · Σ 1/(h_sat(T_i) − h_air,i), T_i = T_cold + {0.1,0.4,0.6,0.9}·Range (Chebyshev)
B4: Inlet air enthalpy h_sat(T_wb) | C4: =(0.24*('Dashboard'!$C$9)+0.62198*(0.61094*EXP(17.625*(('Dashboard'!$C$9)-32)/1.8/((('Dashboard'!$C$9)-32)/1.8+243.04)))/('Cooling Tower & Corrugated Fill'!$C$14-(0.61094*EXP(17.625*(('Dashboard'!$C$9)-32)/1.8/((('Dashboard'!$C$9)-32)/1.8+243.04))))*(1061+0.444*('Dashboard'!$C$9))) | D4: BTU/lb
B6: Approach (°F) | C6: T_cold (°F) | D6: Δh @0.1R | E6: Δh @0.4R | F6: Δh @0.6R | G6: Δh @0.9R | H6: Required KaV/L
B7: 0.1 | C7: ='Dashboard'!$C$9+B7 | D7: =(0.24*((C7+0.1*'Cooling Tower & Corrugated Fill'!$C$12))+0.62198*(0.61094*EXP(17.625*(((C7+0.1*'Cooling Tower & Corrugated Fill'!$C$12))-32)/1.8/((((C7+0.1*'Cooling Tower & Corrugated Fill'!$C$12))-32)/1.8+243.04)))/('Cooling Tower & Corrugated Fill'!$C$14-(0.61094*EXP(17.625*(((C7+0.1*'Cooling Tower & Corrugated Fill'!$C$12))-32)/1.8/((((C7+0.1*'Cooling Tower & Corrugated Fill'!$C$12))-32)/1.8+243.04))))*(1061+0.444*((C7+0.1*'Cooling Tower & Corrugated Fill'!$C$12))))-('Merkel Solver'!$C$4+'Cooling Tower & Corrugated Fill'!$C$13*0.1*'Cooling Tower & Corrugated Fill'!$C$12) | E7: =(0.24*((C7+0.4*'Cooling Tower & Corrugated Fill'!$C$12))+0.62198*(0.61094*EXP(17.625*(((C7+0.4*'Cooling Tower & Corrugated Fill'!$C$12))-32)/1.8/((((C7+0.4*'Cooling Tower & Corrugated Fill'!$C$12))-32)/1.8+243.04)))/('Cooling Tower & Corrugated Fill'!$C$14-(0.61094*EXP(17.625*(((C7+0.4*'Cooling Tower & Corrugated Fill'!$C$12))-32)/1.8/((((C7+0.4*'Cooling Tower & Corrugated Fill'!$C$12))-32)/1.8+243.04))))*(1061+0.444*((C7+0.4*'Cooling Tower & Corrugated Fill'!$C$12))))-('Merkel Solver'!$C$4+'Cooling Tower & Corrugated Fill'!$C$13*0.4*'Cooling Tower & Corrugated Fill'!$C$12) | F7: =(0.24*((C7+0.6*'Cooling Tower & Corrugated Fill'!$C$12))+0.62198*(0.61094*EXP(17.625*(((C7+0.6*'Cooling Tower & Corrugated Fill'!$C$12))-32)/1.8/((((C7+0.6*'Cooling Tower & Corrugated Fill'!$C$12))-32)/1.8+243.04)))/('Cooling Tower & Corrugated Fill'!$C$14-(0.61094*EXP(17.625*(((C7+0.6*'Cooling Tower & Corrugated Fill'!$C$12))-32)/1.8/((((C7+0.6*'Cooling Tower & Corrugated Fill'!$C$12))-32)/1.8+243.04))))*(1061+0.444*((C7+0.6*'Cooling Tower & Corrugated Fill'!$C$12))))-('Merkel Solver'!$C$4+'Cooling Tower & Corrugated Fill'!$C$13*0.6*'Cooling Tower & Corrugated Fill'!$C$12) | G7: =(0.24*((C7+0.9*'Cooling Tower & Corrugated Fill'!$C$12))+0.62198*(0.61094*EXP(17.625*(((C7+0.9*'Cooling Tower & Corrugated Fill'!$C$12))-32)/1.8/((((C7+0.9*'Cooling Tower & Corrugated Fill'!$C$12))-32)/1.8+243.04)))/('Cooling Tower & Corrugated Fill'!$C$14-(0.61094*EXP(17.625*(((C7+0.9*'Cooling Tower & Corrugated Fill'!$C$12))-32)/1.8/((((C7+0.9*'Cooling Tower & Corrugated Fill'!$C$12))-32)/1.8+243.04))))*(1061+0.444*((C7+0.9*'Cooling Tower & Corrugated Fill'!$C$12))))-('Merkel Solver'!$C$4+'Cooling Tower & Corrugated Fill'!$C$13*0.9*'Cooling Tower & Corrugated Fill'!$C$12) | H7: =IF(MIN(D7:G7)<=0,99999,'Cooling Tower & Corrugated Fill'!$C$12/4*(1/D7+1/E7+1/F7+1/G7))
B8: 0.2 | C8: ='Dashboard'!$C$9+B8 | D8: =(0.24*((C8+0.1*'Cooling Tower & Corrugated Fill'!$C$12))+0.62198*(0.61094*EXP(17.625*(((C8+0.1*'Cooling Tower & Corrugated Fill'!$C$12))-32)/1.8/((((C8+0.1*'Cooling Tower & Corrugated Fill'!$C$12))-32)/1.8+243.04)))/('Cooling Tower & Corrugated Fill'!$C$14-(0.61094*EXP(17.625*(((C8+0.1*'Cooling Tower & Corrugated Fill'!$C$12))-32)/1.8/((((C8+0.1*'Cooling Tower & Corrugated Fill'!$C$12))-32)/1.8+243.04))))*(1061+0.444*((C8+0.1*'Cooling Tower & Corrugated Fill'!$C$12))))-('Merkel Solver'!$C$4+'Cooling Tower & Corrugated Fill'!$C$13*0.1*'Cooling Tower & Corrugated Fill'!$C$12) | E8: =(0.24*((C8+0.4*'Cooling Tower & Corrugated Fill'!$C$12))+0.62198*(0.61094*EXP(17.625*(((C8+0.4*'Cooling Tower & Corrugated Fill'!$C$12))-32)/1.8/((((C8+0.4*'Cooling Tower & Corrugated Fill'!$C$12))-32)/1.8+243.04)))/('Cooling Tower & Corrugated Fill'!$C$14-(0.61094*EXP(17.625*(((C8+0.4*'Cooling Tower & Corrugated Fill'!$C$12))-32)/1.8/((((C8+0.4*'Cooling Tower & Corrugated Fill'!$C$12))-32)/1.8+243.04))))*(1061+0.444*((C8+0.4*'Cooling Tower & Corrugated Fill'!$C$12))))-('Merkel Solver'!$C$4+'Cooling Tower & Corrugated Fill'!$C$13*0.4*'Cooling Tower & Corrugated Fill'!$C$12) | F8: =(0.24*((C8+0.6*'Cooling Tower & Corrugated Fill'!$C$12))+0.62198*(0.61094*EXP(17.625*(((C8+0.6*'Cooling Tower & Corrugated Fill'!$C$12))-32)/1.8/((((C8+0.6*'Cooling Tower & Corrugated Fill'!$C$12))-32)/1.8+243.04)))/('Cooling Tower & Corrugated Fill'!$C$14-(0.61094*EXP(17.625*(((C8+0.6*'Cooling Tower & Corrugated Fill'!$C$12))-32)/1.8/((((C8+0.6*'Cooling Tower & Corrugated Fill'!$C$12))-32)/1.8+243.04))))*(1061+0.444*((C8+0.6*'Cooling Tower & Corrugated Fill'!$C$12))))-('Merkel Solver'!$C$4+'Cooling Tower & Corrugated Fill'!$C$13*0.6*'Cooling Tower & Corrugated Fill'!$C$12) | G8: =(0.24*((C8+0.9*'Cooling Tower & Corrugated Fill'!$C$12))+0.62198*(0.61094*EXP(17.625*(((C8+0.9*'Cooling Tower & Corrugated Fill'!$C$12))-32)/1.8/((((C8+0.9*'Cooling Tower & Corrugated Fill'!$C$12))-32)/1.8+243.04)))/('Cooling Tower & Corrugated Fill'!$C$14-(0.61094*EXP(17.625*(((C8+0.9*'Cooling Tower & Corrugated Fill'!$C$12))-32)/1.8/((((C8+0.9*'Cooling Tower & Corrugated Fill'!$C$12))-32)/1.8+243.04))))*(1061+0.444*((C8+0.9*'Cooling Tower & Corrugated Fill'!$C$12))))-('Merkel Solver'!$C$4+'Cooling Tower & Corrugated Fill'!$C$13*0.9*'Cooling Tower & Corrugated Fill'!$C$12) | H8: =IF(MIN(D8:G8)<=0,99999,'Cooling Tower & Corrugated Fill'!$C$12/4*(1/D8+1/E8+1/F8+1/G8))
B9: 0.3 | C9: ='Dashboard'!$C$9+B9 | D9: =(0.24*((C9+0.1*'Cooling Tower & Corrugated Fill'!$C$12))+0.62198*(0.61094*EXP(17.625*(((C9+0.1*'Cooling Tower & Corrugated Fill'!$C$12))-32)/1.8/((((C9+0.1*'Cooling Tower & Corrugated Fill'!$C$12))-32)/1.8+243.04)))/('Cooling Tower & Corrugated Fill'!$C$14-(0.61094*EXP(17.625*(((C9+0.1*'Cooling Tower & Corrugated Fill'!$C$12))-32)/1.8/((((C9+0.1*'Cooling Tower & Corrugated Fill'!$C$12))-32)/1.8+243.04))))*(1061+0.444*((C9+0.1*'Cooling Tower & Corrugated Fill'!$C$12))))-('Merkel Solver'!$C$4+'Cooling Tower & Corrugated Fill'!$C$13*0.1*'Cooling Tower & Corrugated Fill'!$C$12) | E9: =(0.24*((C9+0.4*'Cooling Tower & Corrugated Fill'!$C$12))+0.62198*(0.61094*EXP(17.625*(((C9+0.4*'Cooling Tower & Corrugated Fill'!$C$12))-32)/1.8/((((C9+0.4*'Cooling Tower & Corrugated Fill'!$C$12))-32)/1.8+243.04)))/('Cooling Tower & Corrugated Fill'!$C$14-(0.61094*EXP(17.625*(((C9+0.4*'Cooling Tower & Corrugated Fill'!$C$12))-32)/1.8/((((C9+0.4*'Cooling Tower & Corrugated Fill'!$C$12))-32)/1.8+243.04))))*(1061+0.444*((C9+0.4*'Cooling Tower & Corrugated Fill'!$C$12))))-('Merkel Solver'!$C$4+'Cooling Tower & Corrugated Fill'!$C$13*0.4*'Cooling Tower & Corrugated Fill'!$C$12) | F9: =(0.24*((C9+0.6*'Cooling Tower & Corrugated Fill'!$C$12))+0.62198*(0.61094*EXP(17.625*(((C9+0.6*'Cooling Tower & Corrugated Fill'!$C$12))-32)/1.8/((((C9+0.6*'Cooling Tower & Corrugated Fill'!$C$12))-32)/1.8+243.04)))/('Cooling Tower & Corrugated Fill'!$C$14-(0.61094*EXP(17.625*(((C9+0.6*'Cooling Tower & Corrugated Fill'!$C$12))-32)/1.8/((((C9+0.6*'Cooling Tower & Corrugated Fill'!$C$12))-32)/1.8+243.04))))*(1061+0.444*((C9+0.6*'Cooling Tower & Corrugated Fill'!$C$12))))-('Merkel Solver'!$C$4+'Cooling Tower & Corrugated Fill'!$C$13*0.6*'Cooling Tower & Corrugated Fill'!$C$12) | G9: =(0.24*((C9+0.9*'Cooling Tower & Corrugated Fill'!$C$12))+0.62198*(0.61094*EXP(17.625*(((C9+0.9*'Cooling Tower & Corrugated Fill'!$C$12))-32)/1.8/((((C9+0.9*'Cooling Tower & Corrugated Fill'!$C$12))-32)/1.8+243.04)))/('Cooling Tower & Corrugated Fill'!$C$14-(0.61094*EXP(17.625*(((C9+0.9*'Cooling Tower & Corrugated Fill'!$C$12))-32)/1.8/((((C9+0.9*'Cooling Tower & Corrugated Fill'!$C$12))-32)/1.8+243.04))))*(1061+0.444*((C9+0.9*'Cooling Tower & Corrugated Fill'!$C$12))))-('Merkel Solver'!$C$4+'Cooling Tower & Corrugated Fill'!$C$13*0.9*'Cooling Tower & Corrugated Fill'!$C$12) | H9: =IF(MIN(D9:G9)<=0,99999,'Cooling Tower & Corrugated Fill'!$C$12/4*(1/D9+1/E9+1/F9+1/G9))
B10: 0.4 | C10: ='Dashboard'!$C$9+B10 | D10: =(0.24*((C10+0.1*'Cooling Tower & Corrugated Fill'!$C$12))+0.62198*(0.61094*EXP(17.625*(((C10+0.1*'Cooling Tower & Corrugated Fill'!$C$12))-32)/1.8/((((C10+0.1*'Cooling Tower & Corrugated Fill'!$C$12))-32)/1.8+243.04)))/('Cooling Tower & Corrugated Fill'!$C$14-(0.61094*EXP(17.625*(((C10+0.1*'Cooling Tower & Corrugated Fill'!$C$12))-32)/1.8/((((C10+0.1*'Cooling Tower & Corrugated Fill'!$C$12))-32)/1.8+243.04))))*(1061+0.444*((C10+0.1*'Cooling Tower & Corrugated Fill'!$C$12))))-('Merkel Solver'!$C$4+'Cooling Tower & Corrugated Fill'!$C$13*0.1*'Cooling Tower & Corrugated Fill'!$C$12) | E10: =(0.24*((C10+0.4*'Cooling Tower & Corrugated Fill'!$C$12))+0.62198*(0.61094*EXP(17.625*(((C10+0.4*'Cooling Tower & Corrugated Fill'!$C$12))-32)/1.8/((((C10+0.4*'Cooling Tower & Corrugated Fill'!$C$12))-32)/1.8+243.04)))/('Cooling Tower & Corrugated Fill'!$C$14-(0.61094*EXP(17.625*(((C10+0.4*'Cooling Tower & Corrugated Fill'!$C$12))-32)/1.8/((((C10+0.4*'Cooling Tower & Corrugated Fill'!$C$12))-32)/1.8+243.04))))*(1061+0.444*((C10+0.4*'Cooling Tower & Corrugated Fill'!$C$12))))-('Merkel Solver'!$C$4+'Cooling Tower & Corrugated Fill'!$C$13*0.4*'Cooling Tower & Corrugated Fill'!$C$12) | F10: =(0.24*((C10+0.6*'Cooling Tower & Corrugated Fill'!$C$12))+0.62198*(0.61094*EXP(17.625*(((C10+0.6*'Cooling Tower & Corrugated Fill'!$C$12))-32)/1.8/((((C10+0.6*'Cooling Tower & Corrugated Fill'!$C$12))-32)/1.8+243.04)))/('Cooling Tower & Corrugated Fill'!$C$14-(0.61094*EXP(17.625*(((C10+0.6*'Cooling Tower & Corrugated Fill'!$C$12))-32)/1.8/((((C10+0.6*'Cooling Tower & Corrugated Fill'!$C$12))-32)/1.8+243.04))))*(1061+0.444*((C10+0.6*'Cooling Tower & Corrugated Fill'!$C$12))))-('Merkel Solver'!$C$4+'Cooling Tower & Corrugated Fill'!$C$13*0.6*'Cooling Tower & Corrugated Fill'!$C$12) | G10: =(0.24*((C10+0.9*'Cooling Tower & Corrugated Fill'!$C$12))+0.62198*(0.61094*EXP(17.625*(((C10+0.9*'Cooling Tower & Corrugated Fill'!$C$12))-32)/1.8/((((C10+0.9*'Cooling Tower & Corrugated Fill'!$C$12))-32)/1.8+243.04)))/('Cooling Tower & Corrugated Fill'!$C$14-(0.61094*EXP(17.625*(((C10+0.9*'Cooling Tower & Corrugated Fill'!$C$12))-32)/1.8/((((C10+0.9*'Cooling Tower & Corrugated Fill'!$C$12))-32)/1.8+243.04))))*(1061+0.444*((C10+0.9*'Cooling Tower & Corrugated Fill'!$C$12))))-('Merkel Solver'!$C$4+'Cooling Tower & Corrugated Fill'!$C$13*0.9*'Cooling Tower & Corrugated Fill'!$C$12) | H10: =IF(MIN(D10:G10)<=0,99999,'Cooling Tower & Corrugated Fill'!$C$12/4*(1/D10+1/E10+1/F10+1/G10))
B11: 0.5 | C11: ='Dashboard'!$C$9+B11 | D11: =(0.24*((C11+0.1*'Cooling Tower & Corrugated Fill'!$C$12))+0.62198*(0.61094*EXP(17.625*(((C11+0.1*'Cooling Tower & Corrugated Fill'!$C$12))-32)/1.8/((((C11+0.1*'Cooling Tower & Corrugated Fill'!$C$12))-32)/1.8+243.04)))/('Cooling Tower & Corrugated Fill'!$C$14-(0.61094*EXP(17.625*(((C11+0.1*'Cooling Tower & Corrugated Fill'!$C$12))-32)/1.8/((((C11+0.1*'Cooling Tower & Corrugated Fill'!$C$12))-32)/1.8+243.04))))*(1061+0.444*((C11+0.1*'Cooling Tower & Corrugated Fill'!$C$12))))-('Merkel Solver'!$C$4+'Cooling Tower & Corrugated Fill'!$C$13*0.1*'Cooling Tower & Corrugated Fill'!$C$12) | E11: =(0.24*((C11+0.4*'Cooling Tower & Corrugated Fill'!$C$12))+0.62198*(0.61094*EXP(17.625*(((C11+0.4*'Cooling Tower & Corrugated Fill'!$C$12))-32)/1.8/((((C11+0.4*'Cooling Tower & Corrugated Fill'!$C$12))-32)/1.8+243.04)))/('Cooling Tower & Corrugated Fill'!$C$14-(0.61094*EXP(17.625*(((C11+0.4*'Cooling Tower & Corrugated Fill'!$C$12))-32)/1.8/((((C11+0.4*'Cooling Tower & Corrugated Fill'!$C$12))-32)/1.8+243.04))))*(1061+0.444*((C11+0.4*'Cooling Tower & Corrugated Fill'!$C$12))))-('Merkel Solver'!$C$4+'Cooling Tower & Corrugated Fill'!$C$13*0.4*'Cooling Tower & Corrugated Fill'!$C$12) | F11: =(0.24*((C11+0.6*'Cooling Tower & Corrugated Fill'!$C$12))+0.62198*(0.61094*EXP(17.625*(((C11+0.6*'Cooling Tower & Corrugated Fill'!$C$12))-32)/1.8/((((C11+0.6*'Cooling Tower & Corrugated Fill'!$C$12))-32)/1.8+243.04)))/('Cooling Tower & Corrugated Fill'!$C$14-(0.61094*EXP(17.625*(((C11+0.6*'Cooling Tower & Corrugated Fill'!$C$12))-32)/1.8/((((C11+0.6*'Cooling Tower & Corrugated Fill'!$C$12))-32)/1.8+243.04))))*(1061+0.444*((C11+0.6*'Cooling Tower & Corrugated Fill'!$C$12))))-('Merkel Solver'!$C$4+'Cooling Tower & Corrugated Fill'!$C$13*0.6*'Cooling Tower & Corrugated Fill'!$C$12) | G11: =(0.24*((C11+0.9*'Cooling Tower & Corrugated Fill'!$C$12))+0.62198*(0.61094*EXP(17.625*(((C11+0.9*'Cooling Tower & Corrugated Fill'!$C$12))-32)/1.8/((((C11+0.9*'Cooling Tower & Corrugated Fill'!$C$12))-32)/1.8+243.04)))/('Cooling Tower & Corrugated Fill'!$C$14-(0.61094*EXP(17.625*(((C11+0.9*'Cooling Tower & Corrugated Fill'!$C$12))-32)/1.8/((((C11+0.9*'Cooling Tower & Corrugated Fill'!$C$12))-32)/1.8+243.04))))*(1061+0.444*((C11+0.9*'Cooling Tower & Corrugated Fill'!$C$12))))-('Merkel Solver'!$C$4+'Cooling Tower & Corrugated Fill'!$C$13*0.9*'Cooling Tower & Corrugated Fill'!$C$12) | H11: =IF(MIN(D11:G11)<=0,99999,'Cooling Tower & Corrugated Fill'!$C$12/4*(1/D11+1/E11+1/F11+1/G11))
B12: 0.6 | C12: ='Dashboard'!$C$9+B12 | D12: =(0.24*((C12+0.1*'Cooling Tower & Corrugated Fill'!$C$12))+0.62198*(0.61094*EXP(17.625*(((C12+0.1*'Cooling Tower & Corrugated Fill'!$C$12))-32)/1.8/((((C12+0.1*'Cooling Tower & Corrugated Fill'!$C$12))-32)/1.8+243.04)))/('Cooling Tower & Corrugated Fill'!$C$14-(0.61094*EXP(17.625*(((C12+0.1*'Cooling Tower & Corrugated Fill'!$C$12))-32)/1.8/((((C12+0.1*'Cooling Tower & Corrugated Fill'!$C$12))-32)/1.8+243.04))))*(1061+0.444*((C12+0.1*'Cooling Tower & Corrugated Fill'!$C$12))))-('Merkel Solver'!$C$4+'Cooling Tower & Corrugated Fill'!$C$13*0.1*'Cooling Tower & Corrugated Fill'!$C$12) | E12: =(0.24*((C12+0.4*'Cooling Tower & Corrugated Fill'!$C$12))+0.62198*(0.61094*EXP(17.625*(((C12+0.4*'Cooling Tower & Corrugated Fill'!$C$12))-32)/1.8/((((C12+0.4*'Cooling Tower & Corrugated Fill'!$C$12))-32)/1.8+243.04)))/('Cooling Tower & Corrugated Fill'!$C$14-(0.61094*EXP(17.625*(((C12+0.4*'Cooling Tower & Corrugated Fill'!$C$12))-32)/1.8/((((C12+0.4*'Cooling Tower & Corrugated Fill'!$C$12))-32)/1.8+243.04))))*(1061+0.444*((C12+0.4*'Cooling Tower & Corrugated Fill'!$C$12))))-('Merkel Solver'!$C$4+'Cooling Tower & Corrugated Fill'!$C$13*0.4*'Cooling Tower & Corrugated Fill'!$C$12) | F12: =(0.24*((C12+0.6*'Cooling Tower & Corrugated Fill'!$C$12))+0.62198*(0.61094*EXP(17.625*(((C12+0.6*'Cooling Tower & Corrugated Fill'!$C$12))-32)/1.8/((((C12+0.6*'Cooling Tower & Corrugated Fill'!$C$12))-32)/1.8+243.04)))/('Cooling Tower & Corrugated Fill'!$C$14-(0.61094*EXP(17.625*(((C12+0.6*'Cooling Tower & Corrugated Fill'!$C$12))-32)/1.8/((((C12+0.6*'Cooling Tower & Corrugated Fill'!$C$12))-32)/1.8+243.04))))*(1061+0.444*((C12+0.6*'Cooling Tower & Corrugated Fill'!$C$12))))-('Merkel Solver'!$C$4+'Cooling Tower & Corrugated Fill'!$C$13*0.6*'Cooling Tower & Corrugated Fill'!$C$12) | G12: =(0.24*((C12+0.9*'Cooling Tower & Corrugated Fill'!$C$12))+0.62198*(0.61094*EXP(17.625*(((C12+0.9*'Cooling Tower & Corrugated Fill'!$C$12))-32)/1.8/((((C12+0.9*'Cooling Tower & Corrugated Fill'!$C$12))-32)/1.8+243.04)))/('Cooling Tower & Corrugated Fill'!$C$14-(0.61094*EXP(17.625*(((C12+0.9*'Cooling Tower & Corrugated Fill'!$C$12))-32)/1.8/((((C12+0.9*'Cooling Tower & Corrugated Fill'!$C$12))-32)/1.8+243.04))))*(1061+0.444*((C12+0.9*'Cooling Tower & Corrugated Fill'!$C$12))))-('Merkel Solver'!$C$4+'Cooling Tower & Corrugated Fill'!$C$13*0.9*'Cooling Tower & Corrugated Fill'!$C$12) | H12: =IF(MIN(D12:G12)<=0,99999,'Cooling Tower & Corrugated Fill'!$C$12/4*(1/D12+1/E12+1/F12+1/G12))
